Internal Server Error: /checkout_v2/checkout/
Traceback (most recent call last):
  File "/workspace/.pip-modules/lib/python3.12/site-packages/django/utils/datastructures.py", line 84, in __getitem__
    list_ = super().__getitem__(key)
            ^^^^^^^^^^^^^^^^^^^^^^^^
KeyError: 'postcode'

During handling of the above exception, another exception occurred:

Traceback (most recent call last):
  File "/workspace/.pip-modules/lib/python3.12/site-packages/django/core/handlers/exception.py", line 55, in inner
    response = get_response(request)
               ^^^^^^^^^^^^^^^^^^^^^
  File "/workspace/.pip-modules/lib/python3.12/site-packages/django/core/handlers/base.py", line 197, in _get_response
    response = wrapped_callback(request, *callback_args, **callback_kwargs)
               ^^^^^^^^^^^^^^^^^^^^^^^^^^^^^^^^^^^^^^^^^^^^^^^^^^^^^^^^^^^^
  File "/workspace/runplanner-training/checkout_v2/views.py", line 51, in checkout
    'postcode': request.POST['postcode'],
                ~~~~~~~~~~~~^^^^^^^^^^^^
  File "/workspace/.pip-modules/lib/python3.12/site-packages/django/utils/datastructures.py", line 86, in __getitem__
    raise MultiValueDictKeyError(key)
django.utils.datastructures.MultiValueDictKeyError: 'postcode'
"POST /checkout_v2/checkout/ HTTP/1.1" 500 90883
Internal Server Error: /checkout_v2/checkout/
Traceback (most recent call last):
  File "/workspace/.pip-modules/lib/python3.12/site-packages/django/core/handlers/exception.py", line 55, in inner
    response = get_response(request)
               ^^^^^^^^^^^^^^^^^^^^^
  File "/workspace/.pip-modules/lib/python3.12/site-packages/django/core/handlers/base.py", line 197, in _get_response
    response = wrapped_callback(request, *callback_args, **callback_kwargs)
               ^^^^^^^^^^^^^^^^^^^^^^^^^^^^^^^^^^^^^^^^^^^^^^^^^^^^^^^^^^^^
  File "/workspace/runplanner-training/checkout_v2/views.py", line 59, in checkout
    pid = request.POST.get('client_secret').split('_secret')[0]
          ^^^^^^^^^^^^^^^^^^^^^^^^^^^^^^^^^^^^^^^
AttributeError: 'NoneType' object has no attribute 'split'
"POST /checkout_v2/checkout/ HTTP/1.1" 500 82892
Internal Server Error: /checkout_v2/checkout/
Traceback (most recent call last):
  File "/workspace/.pip-modules/lib/python3.12/site-packages/django/core/handlers/exception.py", line 55, in inner
    response = get_response(request)
               ^^^^^^^^^^^^^^^^^^^^^
  File "/workspace/.pip-modules/lib/python3.12/site-packages/django/core/handlers/base.py", line 197, in _get_response
    response = wrapped_callback(request, *callback_args, **callback_kwargs)
               ^^^^^^^^^^^^^^^^^^^^^^^^^^^^^^^^^^^^^^^^^^^^^^^^^^^^^^^^^^^^
  File "/workspace/runplanner-training/checkout_v2/views.py", line 59, in checkout
    pid = request.POST.get('client_secret').split('_secret')[0]
          ^^^^^^^^^^^^^^^^^^^^^^^^^^^^^^^^^^^^^^^
AttributeError: 'NoneType' object has no attribute 'split'
"POST /checkout_v2/checkout/ HTTP/1.1" 500 82892
